<?xml version="1.0" encoding="utf-8"?>
<!-- This URDF was automatically created by SolidWorks to URDF Exporter! Originally created by Stephen Brawner (brawner@gmail.com) 
     Commit Version: 1.6.0-4-g7f85cfe  Build Version: 1.6.7995.38578
     For more information, please see http://wiki.ros.org/sw_urdf_exporter -->
<robot name="my_robot" xmlns:xacro="http://www.ros.org/wiki/xacro">
  
  <link name="robot_footprint">
  </link>
  <link name="base_link">
    <!-- <pose>0 0 0.04 0 0 0</pose> -->
    <inertial>
      <origin xyz="0 0 0" rpy="0 0 0" />
      <mass value="13.85" />
      <inertia ixx="0.094768" ixy="5.1625E-06" ixz="0.017784" iyy="0.2104" iyz="-3.9186E-06" izz="0.23604" />
    </inertial>
    <visual>
      <origin xyz="0 0 0" rpy="0 0 0" />
      <geometry>
        <mesh filename="package://my_robot/meshes/base_link.STL" />
      </geometry>
      <material name="">
        <color rgba="0.254 0.329 0.4 1" />
      </material>
    </visual>
    <collision>
      <origin xyz="0 0 0" rpy="0 0 0" />
      <geometry>
        <mesh filename="package://my_robot/meshes/base_link.STL" />
      </geometry>
    </collision>
  </link>
  <link name="left_wheel">
    <inertial>
      <origin xyz="-0.04 -0.03 -0.03" rpy="0 0 0" />
      <mass value="0.61508" />
      <inertia ixx="0.0010294" ixy="1.014E-13" ixz="2.613E-13" iyy="0.0010294" iyz="-3.4572E-14" izz="0.0016534" />
    </inertial>
    <visual>
      <origin xyz="-0.04 -0.03 -0.03" rpy="0 0 0" />
      <geometry>
        <mesh filename="package://my_robot/meshes/left_wheel.STL" />
      </geometry>
      <material name="">
        <color rgba="0.211 0.211 0.211 1" />
      </material>
    </visual>
    <collision>
      <origin xyz="-0.04 -0.03 -0.03" rpy="0 0 0" />
      <geometry>
        <mesh filename="package://my_robot/meshes/left_wheel.STL" />
      </geometry>
    </collision>
  </link>

  <link name="right_wheel">
    <inertial>
      <origin xyz="-0.04 -0.03 0.03" rpy="0 0 0" />
      <mass value="0.61508" />
      <inertia ixx="0.0010294" ixy="1.014E-13" ixz="2.613E-13" iyy="0.0010294" iyz="-3.4573E-14" izz="0.0016534" />
    </inertial>
    <visual>
      <origin xyz="-0.04 -0.03 0.03" rpy="0 0 0" />
      <geometry>
        <mesh filename="package://my_robot/meshes/right_wheel.STL" />
      </geometry>
      <material name="">
        <color rgba="0.211 0.211 0.211 1" />
      </material>
    </visual>
    <collision>
      <origin xyz="-0.04 -0.03 0.03" rpy="0 0 0" />
      <geometry>
        <mesh filename="package://my_robot/meshes/right_wheel.STL" />
      </geometry>
    </collision>
  </link>

  <link name='camera'>
    <inertial>
      <mass value="0.1" />
      <origin xyz="0.0 0 0" rpy=" 0 0 0" />
      <inertia ixx="1e-6" ixy="0" ixz="0" iyy="1e-6" iyz="0" izz="1e-6" />
    </inertial>

    <collision name='camera_collision'>
      <origin xyz="0.0 0 0" rpy=" 0 0 0" />
      <geometry>
        <box size="0.05 0.05 0.05" />
      </geometry>
    </collision>

    <visual name='camera_visual'>
      <origin xyz="0.0 0 0" rpy=" 0 0 0" />
      <geometry>
        <box size="0.05 0.05 0.05" />
      </geometry>
      <material name="">
        <color rgba="0.592 0.819 0.725 1" />
      </material>
    </visual>
  </link>
  <link name='hokuyo'>
    <inertial>
      <mass value="1e-5" />
      <origin xyz="0 0 0" rpy=" 0 0 0" />
      <inertia ixx="1e-6" ixy="0" ixz="0" iyy="1e-6" iyz="0" izz="1e-6" />
    </inertial>

    <collision name='hokuyo_collision'>
      <origin xyz="0.0 0 0" rpy=" 0 0 0" />
      <geometry>
        <box size="0.1 0.1 0.1" />
      </geometry>
    </collision>

    <visual name='hokuyo_visual'>
      <origin xyz="0.0 0 0" rpy=" 0 0 0" />
      <geometry>
        <mesh filename="package://my_robot/meshes/hokuyo.dae" />
      </geometry>
    </visual>
  </link>

  <joint name="base_joint" type="fixed">
    <parent link="robot_footprint"/>
    <child link="base_link" />
    <origin xyz="0 0 0.04" rpy="1.5708 0 3.14"/>
  </joint>
  <joint name="base_link_left_wheel" type="continuous">
    <origin xyz="0.04 0.03 0.03" rpy="0 0 0" />
    <parent link="base_link" />
    <child link="left_wheel" />
    <axis xyz="0 0 1" />
    <limit effort="1" velocity="1" />
  </joint>
  <joint name="base_link_right_wheel" type="continuous">
    <origin xyz="0.04 0.03 -0.03" rpy="0 0 0" />
    <parent link="base_link" />
    <child link="right_wheel" />
    <axis xyz="0 0 1" />
    <limit effort="1" velocity="1" />
  </joint>
  <joint type="fixed" name="camera_joint">
    <origin xyz="-0.2 0.05 0" rpy="1.5707 0 3.14" />
    <child link="camera" />
    <parent link="base_link" />
    <axis xyz="0 1 0" rpy="0 0 0" />
  </joint>
  <joint type="fixed" name="hokuyo_joint">
    <origin xyz="0 0.2 0" rpy="1.5707 0 3.14" />
    <child link="hokuyo" />
    <parent link="base_link" />
    <axis xyz="1 0 0" rpy="0 0 0" />
  </joint>

  <gazebo reference="base_link">
    <material name="">
      Gazebo/Turquoise
    </material>
  </gazebo>
  <gazebo reference="left_wheel">
    <material name="">
      Gazebo/DarkGrey
    </material>
  </gazebo>
  <gazebo reference="right_wheel">
    <material name="">
      Gazebo/DarkGrey
    </material>
  </gazebo>
  <gazebo reference="camera">
    <material name="">
      Gazebo/Gold
    </material>
  </gazebo>

  <xacro:include filename="$(find my_robot)/urdf/my_robot.gazebo" />
</robot>